<?xml version='1.0'?>
<sdf version='1.6'>
    <model name="BlueROV2 Heavy with Camera">
        <pose>0 0 0 0 0 0</pose>

        <link name="base_link">
            <inertial>
                <mass>11</mass>
                <inertia>
                    <ixx>0.1</ixx>
                    <ixy>0</ixy>
                    <ixz>0</ixz>
                    <iyy>0.1</iyy>
                    <iyz>0</iyz>
                    <izz>0.1</izz>
                </inertia>
            </inertial>

            <visual name="base_link_visual">
                <geometry>
                    <mesh>
                        <uri>model://uuv_bluerov2_heavy_cam/meshes/BlueROV2heavy.dae</uri>
                    </mesh>

                    <!-- <cylinder>
                        <radius>.05</radius>
                        <length>0.2</length>
                    </cylinder> -->
                </geometry>
            </visual>

        </link>

        <link name="pressure_sensor_link">
            <inertial>
                <mass>0.001</mass>
                <inertia>
                    <ixx>1.0e-8</ixx>
                    <ixy>0</ixy>
                    <ixz>0</ixz>
                    <iyy>1.0e-8</iyy>
                    <iyz>0</iyz>
                    <izz>1.0e-8</izz>
                </inertia>
            </inertial>
        </link>

        <joint name="pressure_sensor_joint" type="revolute">
            <child>pressure_sensor_link</child>
            <parent>base_link</parent>
            <axis>
                <xyz>0 0 1</xyz>
                <limit>
                    <upper>0</upper>
                    <lower>0</lower>
                </limit>
            </axis>
        </joint>

        <link name="range_sensor_link">
            <pose>0.2 0 0.1 0 0 0</pose>
            <inertial>
                <mass>0.001</mass>
                <inertia>
                    <ixx>1.0e-8</ixx>
                    <ixy>0</ixy>
                    <ixz>0</ixz>
                    <iyy>1.0e-8</iyy>
                    <iyz>0</iyz>
                    <izz>1.0e-8</izz>
                </inertia>
            </inertial>
        </link>

        <joint name="range_sensor_joint" type="revolute">
            <child>range_sensor_link</child>
            <parent>base_link</parent>
            <axis>
                <xyz>0 0 1</xyz>
                <limit>
                    <upper>0</upper>
                    <lower>0</lower>
                </limit>
            </axis>
        </joint>

        <plugin name="pressure_plugin" filename="libgazebo_pressure_plugin.so">
            <robotNamespace />
            <pubRate>50</pubRate>
            <noise>100.0</noise>
        </plugin>

        <plugin name="range_sensor_plugin" filename="libgazebo_range_sensor_plugin.so">
            <robotNamespace />
            <pubRate>7.0</pubRate>
            <rangeNoiseStd>0.1</rangeNoiseStd>
            <fovCamera>100</fovCamera>
            <viewingAngle>140</viewingAngle>
            <dropProb>0.05</dropProb>
            <maxDetectionDist>4.0</maxDetectionDist>
            <distDropProbExponent>2.0</distDropProbExponent>
        </plugin>

        <link name="thruster1">
            <pose>0.14 -0.10 0 0 1.570796 0.78539815</pose>
            <inertial>
                <mass>1e-10</mass>
                <inertia>
                    <ixx>1e-06</ixx>
                    <ixy>0</ixy>
                    <ixz>0</ixz>
                    <iyy>1e-06</iyy>
                    <iyz>0</iyz>
                    <izz>1e-06</izz>
                </inertia>
            </inertial>
            <visual name="thruster1_visual">
                <geometry>
                    <mesh>
                        <scale>1 1 1</scale>
                        <uri>model://uuv_bluerov2_heavy_cam/meshes/prop.dae</uri>
                    </mesh>
                </geometry>
                <material>
                    <script>
                        <name>Gazebo/Green</name>
                        <uri>model://uuv_bluerov2_heavy_cam/meshes/prop.dae</uri>
                    </script>
                </material>
            </visual>
        </link>

        <joint name="thruster1_joint" type="revolute">
            <axis>
                <xyz>0 0 1</xyz>
                <limit>
                    <lower>-1e+16</lower>
                    <upper>1e+16</upper>
                </limit>
            </axis>
            <parent>base_link</parent>
            <child>thruster1</child>
        </joint>

        <link name="thruster2">
            <pose>0.14 0.10 0 0 1.570796 -0.78539815</pose>
            <inertial>
                <mass>1e-10</mass>
                <inertia>
                    <ixx>1e-06</ixx>
                    <ixy>0</ixy>
                    <ixz>0</ixz>
                    <iyy>1e-06</iyy>
                    <iyz>0</iyz>
                    <izz>1e-06</izz>
                </inertia>
            </inertial>
            <visual name="thruster2_visual">
                <geometry>
                    <mesh>
                        <scale>1 1 1</scale>
                        <uri>model://uuv_bluerov2_heavy_cam/meshes/prop.dae</uri>
                    </mesh>
                </geometry>
                <material>
                    <script>
                        <name>Gazebo/Green</name>
                        <uri>file://media/materials/scripts/gazebo.material</uri>
                    </script>
                </material>
            </visual>
        </link>

        <joint name="thruster2_joint" type="revolute">
            <axis>
                <xyz>0 0 1</xyz>
                <limit>
                    <lower>-1e+16</lower>
                    <upper>1e+16</upper>
                </limit>
            </axis>
            <parent>base_link</parent>
            <child>thruster2</child>
        </joint>

        <link name="thruster3">
            <pose>-0.14 -0.10 0 0 1.570796 2.356194</pose>
            <inertial>
                <mass>1e-10</mass>
                <inertia>
                    <ixx>1e-06</ixx>
                    <ixy>0</ixy>
                    <ixz>0</ixz>
                    <iyy>1e-06</iyy>
                    <iyz>0</iyz>
                    <izz>1e-06</izz>
                </inertia>
            </inertial>
            <visual name="thruster3_visual">
                <geometry>
                    <mesh>
                        <scale>1 1 1</scale>
                        <uri>model://uuv_bluerov2_heavy_cam/meshes/prop.dae</uri>
                    </mesh>
                </geometry>
                <material>
                    <script>
                        <name>Gazebo/Blue</name>
                        <uri>file://media/materials/scripts/gazebo.material</uri>
                    </script>
                </material>
            </visual>
        </link>

        <joint name="thruster3_joint" type="revolute">
            <axis>
                <xyz>0 0 1</xyz>
                <limit>
                    <lower>-1e+16</lower>
                    <upper>1e+16</upper>
                </limit>
            </axis>
            <parent>base_link</parent>
            <child>thruster3</child>
        </joint>

        <link name="thruster4">
            <pose>-0.14 0.10 0 0 1.570796 -2.356194</pose>
            <inertial>
                <mass>1e-10</mass>
                <inertia>
                    <ixx>1e-06</ixx>
                    <ixy>0</ixy>
                    <ixz>0</ixz>
                    <iyy>1e-06</iyy>
                    <iyz>0</iyz>
                    <izz>1e-06</izz>
                </inertia>
            </inertial>
            <visual name="thruster4_visual">
                <geometry>
                    <mesh>
                        <scale>1 1 1</scale>
                        <uri>model://uuv_bluerov2_heavy_cam/meshes/prop.dae</uri>
                    </mesh>
                </geometry>
                <material>
                    <script>
                        <name>Gazebo/Blue</name>
                        <uri>file://media/materials/scripts/gazebo.material</uri>
                    </script>
                </material>
            </visual>
        </link>

        <joint name="thruster4_joint" type="revolute">
            <axis>
                <xyz>0 0 1</xyz>
                <limit>
                    <lower>-1e+16</lower>
                    <upper>1e+16</upper>
                </limit>
            </axis>
            <parent>base_link</parent>
            <child>thruster4</child>
        </joint>

        <link name="thruster5">
            <pose>0.12 -0.22 0.06 0 0 0</pose>
            <inertial>
                <mass>1e-10</mass>
                <inertia>
                    <ixx>1e-06</ixx>
                    <ixy>0</ixy>
                    <ixz>0</ixz>
                    <iyy>1e-06</iyy>
                    <iyz>0</iyz>
                    <izz>1e-06</izz>
                </inertia>
            </inertial>
            <visual name="thruster5_visual">
                <geometry>
                    <mesh>
                        <scale>1 1 1</scale>
                        <uri>model://uuv_bluerov2_heavy_cam/meshes/prop.dae</uri>
                    </mesh>
                </geometry>
                <material>
                    <script>
                        <name>Gazebo/Green</name>
                        <uri>file://media/materials/scripts/gazebo.material</uri>
                    </script>
                </material>
            </visual>
        </link>

        <joint name="thruster5_joint" type="revolute">
            <axis>
                <xyz>0 0 1</xyz>
                <limit>
                    <lower>-1e+16</lower>
                    <upper>1e+16</upper>
                </limit>
            </axis>
            <parent>base_link</parent>
            <child>thruster5</child>
        </joint>

        <link name="thruster6">
            <pose>0.12 0.22 0.06 0 0 0</pose>
            <inertial>
                <mass>1e-10</mass>
                <inertia>
                    <ixx>1e-06</ixx>
                    <ixy>0</ixy>
                    <ixz>0</ixz>
                    <iyy>1e-06</iyy>
                    <iyz>0</iyz>
                    <izz>1e-06</izz>
                </inertia>
            </inertial>
            <visual name="thruster6_visual">
                <geometry>
                    <mesh>
                        <scale>1 1 1</scale>
                        <uri>model://uuv_bluerov2_heavy_cam/meshes/prop.dae</uri>
                    </mesh>
                </geometry>
                <material>
                    <script>
                        <name>Gazebo/Blue</name>
                        <uri>file://media/materials/scripts/gazebo.material</uri>
                    </script>
                </material>
            </visual>
        </link>

        <joint name="thruster6_joint" type="revolute">
            <axis>
                <xyz>0 0 1</xyz>
                <limit>
                    <lower>-1e+16</lower>
                    <upper>1e+16</upper>
                </limit>
            </axis>
            <parent>base_link</parent>
            <child>thruster6</child>
        </joint>

        <link name="thruster7">
            <pose>-0.12 -0.22 0.06 0 0 0</pose>
            <inertial>
                <mass>1e-10</mass>
                <inertia>
                    <ixx>1e-06</ixx>
                    <ixy>0</ixy>
                    <ixz>0</ixz>
                    <iyy>1e-06</iyy>
                    <iyz>0</iyz>
                    <izz>1e-06</izz>
                </inertia>
            </inertial>
            <visual name="thruster7_visual">
                <geometry>
                    <mesh>
                        <scale>1 1 1</scale>
                        <uri>model://uuv_bluerov2_heavy_cam/meshes/prop.dae</uri>
                    </mesh>
                </geometry>
                <material>
                    <script>
                        <name>Gazebo/Blue</name>
                        <uri>file://media/materials/scripts/gazebo.material</uri>
                    </script>
                </material>
            </visual>
        </link>

        <joint name="thruster7_joint" type="revolute">
            <axis>
                <xyz>0 0 1</xyz>
                <limit>
                    <lower>-1e+16</lower>
                    <upper>1e+16</upper>
                </limit>
            </axis>
            <parent>base_link</parent>
            <child>thruster7</child>
        </joint>

        <link name="thruster8">
            <pose>-0.12 0.22 0.06 0 0 0</pose>
            <inertial>
                <mass>1e-10</mass>
                <inertia>
                    <ixx>1e-06</ixx>
                    <ixy>0</ixy>
                    <ixz>0</ixz>
                    <iyy>1e-06</iyy>
                    <iyz>0</iyz>
                    <izz>1e-06</izz>
                </inertia>
            </inertial>
            <visual name="thruster8_visual">
                <geometry>
                    <mesh>
                        <scale>1 1 1</scale>
                        <uri>model://uuv_bluerov2_heavy_cam/meshes/prop.dae</uri>
                    </mesh>
                </geometry>
                <material>
                    <script>
                        <name>Gazebo/Green</name>
                        <uri>file://media/materials/scripts/gazebo.material</uri>
                    </script>
                </material>
            </visual>
        </link>

        <joint name="thruster8_joint" type="revolute">
            <axis>
                <xyz>0 0 1</xyz>
                <limit>
                    <lower>-1e+16</lower>
                    <upper>1e+16</upper>
                </limit>
            </axis>
            <parent>base_link</parent>
            <child>thruster8</child>
        </joint>




        <link name="lidar">
          <inertial>
            <pose>-0.020 0 0.161 0 0 0</pose>
            <inertia>
              <ixx>0.001</ixx>
              <ixy>0.000</ixy>
              <ixz>0.000</ixz>
              <iyy>0.001</iyy>
              <iyz>0.000</iyz>
              <izz>0.001</izz>
            </inertia>
            <mass>0.125</mass>
          </inertial>

          <collision name="lidar_sensor_collision">
              <pose>-0.020 0 0.161 0 0 0</pose>
              <geometry>
                <cylinder>
                  <radius>0.0508</radius>
                  <length>0.055</length>
                </cylinder>
              </geometry>
            </collision>

            <visual name="lidar_sensor_visual">
              <pose>-0.032 0 0.171 0 0 0</pose>
              <geometry>
                <mesh>
                  <uri>model://turtlebot3_common_meshes/lds.dae</uri>
                  <scale>0.001 0.001 0.001</scale>
                </mesh>
              </geometry>
            </visual>

            <sensor name="hls_lfcd_lds" type="ray">
              <always_on>1</always_on>
              <visualize>0</visualize>
              <pose>-0.032 0 0.171 0 0 0</pose>
              <update_rate>1800</update_rate>
              <ray>
                <scan>
                  <horizontal>
                    <samples>360</samples>
                    <resolution>1.000000</resolution>
                    <min_angle>0.000000</min_angle>
                    <max_angle>6.280000</max_angle>
                  </horizontal>
                </scan>
                <range>
                  <min>0.120000</min>
                  <max>3.5</max>
                  <resolution>0.015000</resolution>
                </range>
                <noise>
                  <type>gaussian</type>
                  <mean>0.0</mean>
                  <stddev>0.01</stddev>
                </noise>
              </ray>
            </sensor>
          </link>





        <plugin name="magnetometer_plugin" filename="libgazebo_magnetometer_plugin.so">
            <robotNamespace />
            <pubRate>100</pubRate>
            <noiseDensity>0.0004</noiseDensity>
            <randomWalk>6.4e-06</randomWalk>
            <biasCorrelationTime>600</biasCorrelationTime>
            <magTopic>/mag</magTopic>
        </plugin>

        <plugin name="barometer_plugin" filename="libgazebo_barometer_plugin.so">
            <robotNamespace />
            <pubRate>50</pubRate>
            <baroTopic>/baro</baroTopic>
        </plugin>

        <plugin name="uuv_plugin" filename="libgazebo_uuv_plugin.so">
            <robotNamespace />
            <baseLinkName>base_link</baseLinkName>
            <addedMassLinear>0 0 0</addedMassLinear>
            <addedMassAngular>0.0 0.0 0.0</addedMassAngular>
            <dampingLinear>7 7 7</dampingLinear>
            <dampingAngular>0.3 0.3 0.3</dampingAngular>
            <commandSubTopic>/gazebo/command/motor_speed</commandSubTopic>
            <buoyancy>
                <link_name>base_link</link_name>
                <origin>0 0 0.01</origin>
                <compensation>1.001</compensation>
                <height_scale_limit>0.05</height_scale_limit>
            </buoyancy>
        </plugin>

        <plugin name="thruster1_model" filename="libgazebo_motor_model.so">
            <robotNamespace />
            <reversible>true</reversible>
            <jointName>thruster1_joint</jointName>
            <linkName>thruster1</linkName>
            <turningDirection>ccw</turningDirection>
            <timeConstantUp>0.0125</timeConstantUp>
            <timeConstantDown>0.025</timeConstantDown>
            <maxRotVelocity>1100</maxRotVelocity>
            <motorConstant>10</motorConstant>
            <momentConstant>0.01</momentConstant>
            <rotorDragCoefficient>0</rotorDragCoefficient>
            <rollingMomentCoefficient>0</rollingMomentCoefficient>
            <commandSubTopic>/gazebo/command/motor_speed</commandSubTopic>
            <motorNumber>0</motorNumber>
            <motorSpeedPubTopic>/motor_speed/0</motorSpeedPubTopic>
            <rotorVelocitySlowdownSim>0.025</rotorVelocitySlowdownSim>
        </plugin>

        <plugin name="thruster2_model" filename="libgazebo_motor_model.so">
            <robotNamespace />
            <reversible>true</reversible>
            <jointName>thruster2_joint</jointName>
            <linkName>thruster2</linkName>
            <turningDirection>ccw</turningDirection>
            <timeConstantUp>0.0125</timeConstantUp>
            <timeConstantDown>0.025</timeConstantDown>
            <maxRotVelocity>1100</maxRotVelocity>
            <motorConstant>10</motorConstant>
            <momentConstant>0.01</momentConstant>
            <rotorDragCoefficient>0</rotorDragCoefficient>
            <rollingMomentCoefficient>0</rollingMomentCoefficient>
            <commandSubTopic>/gazebo/command/motor_speed</commandSubTopic>
            <motorNumber>1</motorNumber>
            <motorSpeedPubTopic>/motor_speed/1</motorSpeedPubTopic>
            <rotorVelocitySlowdownSim>0.025</rotorVelocitySlowdownSim>
        </plugin>

        <plugin name="thruster3_model" filename="libgazebo_motor_model.so">
            <robotNamespace />
            <reversible>true</reversible>
            <jointName>thruster3_joint</jointName>
            <linkName>thruster3</linkName>
            <turningDirection>ccw</turningDirection>
            <timeConstantUp>0.0125</timeConstantUp>
            <timeConstantDown>0.025</timeConstantDown>
            <maxRotVelocity>1100</maxRotVelocity>
            <motorConstant>-10</motorConstant>
            <momentConstant>-0.01</momentConstant>
            <rotorDragCoefficient>0</rotorDragCoefficient>
            <rollingMomentCoefficient>0</rollingMomentCoefficient>
            <commandSubTopic>/gazebo/command/motor_speed</commandSubTopic>
            <motorNumber>2</motorNumber>
            <motorSpeedPubTopic>/motor_speed/2</motorSpeedPubTopic>
            <rotorVelocitySlowdownSim>0.025</rotorVelocitySlowdownSim>
        </plugin>

        <plugin name="thruster4_model" filename="libgazebo_motor_model.so">
            <robotNamespace />
            <reversible>true</reversible>
            <jointName>thruster4_joint</jointName>
            <linkName>thruster4</linkName>
            <turningDirection>ccw</turningDirection>
            <timeConstantUp>0.0125</timeConstantUp>
            <timeConstantDown>0.025</timeConstantDown>
            <maxRotVelocity>1100</maxRotVelocity>
            <motorConstant>-10</motorConstant>
            <momentConstant>-0.01</momentConstant>
            <rotorDragCoefficient>0</rotorDragCoefficient>
            <rollingMomentCoefficient>0</rollingMomentCoefficient>
            <commandSubTopic>/gazebo/command/motor_speed</commandSubTopic>
            <motorNumber>3</motorNumber>
            <motorSpeedPubTopic>/motor_speed/3</motorSpeedPubTopic>
            <rotorVelocitySlowdownSim>0.025</rotorVelocitySlowdownSim>
        </plugin>

        <plugin name="thruster5_model" filename="libgazebo_motor_model.so">
            <robotNamespace />
            <reversible>true</reversible>
            <jointName>thruster5_joint</jointName>
            <linkName>thruster5</linkName>
            <turningDirection>ccw</turningDirection>
            <timeConstantUp>0.0125</timeConstantUp>
            <timeConstantDown>0.025</timeConstantDown>
            <maxRotVelocity>1100</maxRotVelocity>
            <motorConstant>10</motorConstant>
            <momentConstant>0.01</momentConstant>
            <rotorDragCoefficient>0</rotorDragCoefficient>
            <rollingMomentCoefficient>0</rollingMomentCoefficient>
            <commandSubTopic>/gazebo/command/motor_speed</commandSubTopic>
            <motorNumber>4</motorNumber>
            <motorSpeedPubTopic>/motor_speed/4</motorSpeedPubTopic>
            <rotorVelocitySlowdownSim>0.025</rotorVelocitySlowdownSim>
        </plugin>

        <plugin name="thruster6_model" filename="libgazebo_motor_model.so">
            <robotNamespace />
            <reversible>true</reversible>
            <jointName>thruster6_joint</jointName>
            <linkName>thruster6</linkName>
            <turningDirection>ccw</turningDirection>
            <timeConstantUp>0.0125</timeConstantUp>
            <timeConstantDown>0.025</timeConstantDown>
            <maxRotVelocity>1100</maxRotVelocity>
            <motorConstant>-10</motorConstant>
            <momentConstant>-0.01</momentConstant>
            <rotorDragCoefficient>0</rotorDragCoefficient>
            <rollingMomentCoefficient>0</rollingMomentCoefficient>
            <commandSubTopic>/gazebo/command/motor_speed</commandSubTopic>
            <motorNumber>5</motorNumber>
            <motorSpeedPubTopic>/motor_speed/5</motorSpeedPubTopic>
            <rotorVelocitySlowdownSim>0.025</rotorVelocitySlowdownSim>
        </plugin>

        <plugin name="thruster7_model" filename="libgazebo_motor_model.so">
            <robotNamespace />
            <reversible>true</reversible>
            <jointName>thruster7_joint</jointName>
            <linkName>thruster7</linkName>
            <turningDirection>ccw</turningDirection>
            <timeConstantUp>0.0125</timeConstantUp>
            <timeConstantDown>0.025</timeConstantDown>
            <maxRotVelocity>1100</maxRotVelocity>
            <motorConstant>-10</motorConstant>
            <momentConstant>-0.01</momentConstant>
            <rotorDragCoefficient>0</rotorDragCoefficient>
            <rollingMomentCoefficient>0</rollingMomentCoefficient>
            <commandSubTopic>/gazebo/command/motor_speed</commandSubTopic>
            <motorNumber>6</motorNumber>
            <motorSpeedPubTopic>/motor_speed/6</motorSpeedPubTopic>
            <rotorVelocitySlowdownSim>0.025</rotorVelocitySlowdownSim>
        </plugin>

        <plugin name="thruster8_model" filename="libgazebo_motor_model.so">
            <robotNamespace />
            <reversible>true</reversible>
            <jointName>thruster8_joint</jointName>
            <linkName>thruster8</linkName>
            <turningDirection>ccw</turningDirection>
            <timeConstantUp>0.0125</timeConstantUp>
            <timeConstantDown>0.025</timeConstantDown>
            <maxRotVelocity>1100</maxRotVelocity>
            <motorConstant>10</motorConstant>
            <momentConstant>0.01</momentConstant>
            <rotorDragCoefficient>0</rotorDragCoefficient>
            <rollingMomentCoefficient>0</rollingMomentCoefficient>
            <commandSubTopic>/gazebo/command/motor_speed</commandSubTopic>
            <motorNumber>7</motorNumber>
            <motorSpeedPubTopic>/motor_speed/7</motorSpeedPubTopic>
            <rotorVelocitySlowdownSim>0.025</rotorVelocitySlowdownSim>
        </plugin>

        <plugin name="mavlink_interface" filename="libgazebo_mavlink_interface.so">
            <robotNamespace />
            <imuSubTopic>/imu</imuSubTopic>
            <gpsSubTopic>/gps</gpsSubTopic>
            <magSubTopic>/mag</magSubTopic>
            <baroSubTopic>/baro</baroSubTopic>
            <mavlink_addr>INADDR_ANY</mavlink_addr>
            <mavlink_udp_port>14560</mavlink_udp_port>
            <mavlink_tcp_port>4560</mavlink_tcp_port>
            <serialEnabled>0</serialEnabled>
            <serialDevice>/dev/ttyACM0</serialDevice>
            <baudRate>921600</baudRate>
            <qgc_addr>INADDR_ANY</qgc_addr>
            <qgc_udp_port>14550</qgc_udp_port>
            <sdk_addr>INADDR_ANY</sdk_addr>
            <sdk_udp_port>14540</sdk_udp_port>
            <hil_mode>false</hil_mode>
            <hil_state_level>false</hil_state_level>
            <vehicle_is_tailsitter>false</vehicle_is_tailsitter>
            <send_vision_estimation>true</send_vision_estimation>
            <send_odometry>false</send_odometry>
            <enable_lockstep>true</enable_lockstep>
            <use_tcp>true</use_tcp>
            <motorSpeedCommandPubTopic>/gazebo/command/motor_speed</motorSpeedCommandPubTopic>

            <!-- control channels, this way for every channel different settings can be realized -->
            <control_channels>
                <channel name="thruster1">
                    <input_index>0</input_index>
                    <input_offset>0</input_offset>
                    <input_scaling>1</input_scaling>
                    <zero_position_disarmed>0</zero_position_disarmed>
                    <zero_position_armed>0</zero_position_armed>
                    <joint_control_type>velocity</joint_control_type>
                    <joint_name>thruster1_joint</joint_name>
                </channel>
                <channel name="thruster2">
                    <input_index>1</input_index>
                    <input_offset>0</input_offset>
                    <input_scaling>1</input_scaling>
                    <zero_position_disarmed>0</zero_position_disarmed>
                    <zero_position_armed>0</zero_position_armed>
                    <joint_control_type>velocity</joint_control_type>
                    <joint_name>thruster2_joint</joint_name>
                </channel>
                <channel name="thruster3">
                    <input_index>2</input_index>
                    <input_offset>0</input_offset>
                    <input_scaling>1</input_scaling>
                    <zero_position_disarmed>0</zero_position_disarmed>
                    <zero_position_armed>0</zero_position_armed>
                    <joint_control_type>velocity</joint_control_type>
                    <joint_name>thruster3_joint</joint_name>
                </channel>
                <channel name="thruster4">
                    <input_index>3</input_index>
                    <input_offset>0</input_offset>
                    <input_scaling>1</input_scaling>
                    <zero_position_disarmed>0</zero_position_disarmed>
                    <zero_position_armed>0</zero_position_armed>
                    <joint_control_type>velocity</joint_control_type>
                    <joint_name>thruster4_joint</joint_name>
                </channel>
                <channel name="thruster5">
                    <input_index>4</input_index>
                    <input_offset>0</input_offset>
                    <input_scaling>1</input_scaling>
                    <zero_position_disarmed>0</zero_position_disarmed>
                    <zero_position_armed>0</zero_position_armed>
                    <joint_control_type>velocity</joint_control_type>
                    <joint_name>thruster5_joint</joint_name>
                </channel>
                <channel name="thruster6">
                    <input_index>5</input_index>
                    <input_offset>0</input_offset>
                    <input_scaling>1</input_scaling>
                    <zero_position_disarmed>0</zero_position_disarmed>
                    <zero_position_armed>0</zero_position_armed>
                    <joint_control_type>velocity</joint_control_type>
                    <joint_name>thruster6_joint</joint_name>
                </channel>
                <channel name="thruster7">
                    <input_index>6</input_index>
                    <input_offset>0</input_offset>
                    <input_scaling>1</input_scaling>
                    <zero_position_disarmed>0</zero_position_disarmed>
                    <zero_position_armed>0</zero_position_armed>
                    <joint_control_type>velocity</joint_control_type>
                    <joint_name>thruster7_joint</joint_name>
                </channel>
                <channel name="thruster8">
                    <input_index>7</input_index>
                    <input_offset>0</input_offset>
                    <input_scaling>1</input_scaling>
                    <zero_position_disarmed>0</zero_position_disarmed>
                    <zero_position_armed>0</zero_position_armed>
                    <joint_control_type>velocity</joint_control_type>
                    <joint_name>thruster8_joint</joint_name>
                </channel>
            </control_channels>
        </plugin>

        <plugin name="gazebo_imu_plugin" filename="libgazebo_imu_plugin.so">
            <robotNamespace />
            <linkName>base_link</linkName>
            <imuTopic>/imu</imuTopic>
            <gyroscopeNoiseDensity>0.0003394</gyroscopeNoiseDensity>
            <gyroscopeRandomWalk>3.8785e-05</gyroscopeRandomWalk>
            <gyroscopeBiasCorrelationTime>1000.0</gyroscopeBiasCorrelationTime>
            <gyroscopeTurnOnBiasSigma>0.0087</gyroscopeTurnOnBiasSigma>
            <accelerometerNoiseDensity>0.004</accelerometerNoiseDensity>
            <accelerometerRandomWalk>0.006</accelerometerRandomWalk>
            <accelerometerBiasCorrelationTime>300.0</accelerometerBiasCorrelationTime>
            <accelerometerTurnOnBiasSigma>0.196</accelerometerTurnOnBiasSigma>
        </plugin>

        <plugin name="ground_truth" filename="libgazebo_ros_p3d.so">
            <alwaysOn>true</alwaysOn>
            <updateRate>30.0</updateRate>
            <bodyName>base_link</bodyName>
            <topicName>ground_truth/state</topicName>
            <gaussianNoise>0.0</gaussianNoise>
            <frameName>map</frameName>
            <xyzOffsets>0 0 0</xyzOffsets>
            <rpyOffsets>0 0 0</rpyOffsets>
        </plugin>

        <link name="front_camera_link">
            <pose>0.3 0 0.05 0 0 0</pose>
            <inertial>
                <mass>1e-10</mass>
                <inertia>
                    <ixx>1e-06</ixx>
                    <ixy>0</ixy>
                    <ixz>0</ixz>
                    <iyy>1e-06</iyy>
                    <iyz>0</iyz>
                    <izz>1e-06</izz>
                </inertia>
            </inertial>

            <sensor name="front_camera" type="camera">
                <camera name="front_camera">
                    <horizontal_fov>1.4</horizontal_fov>
                    <image>
                        <width>640</width>
                        <height>480</height>
                        <format>R8G8B8</format>
                    </image>
                    <clip>
                        <near>0.02</near>
                        <far>100</far>
                    </clip>
                    <noise>
                        <type>gaussian</type>
                        <mean>0.0</mean>
                        <stddev>0.007</stddev>
                    </noise>
                    <distortion>
                        <k1>0.0</k1>
                        <k2>0.0</k2>
                        <p1>0.0</p1>
                        <p2>0.0</p2>
                        <k3>0</k3>
                    </distortion>

                    <lens>
                        <type>equidistant</type>
                        <scale_to_hfov>false</scale_to_hfov>
                    </lens>
                </camera>
                <always_on>1</always_on>
                <update_rate>10</update_rate>
                <visualize>1</visualize>

                <plugin name="camera_controller" filename="libgazebo_ros_camera.so">
                    <alwaysOn>1</alwaysOn>
                    <updateRate>0.0</updateRate>
                    <cameraName>front_camera</cameraName>
                    <frameName>bluerov/front_camera/camera_frame</frameName>
                    <imageTopicName>image_raw</imageTopicName>
                    <distortionK1>0.0</distortionK1>
                    <distortionK2>0.0</distortionK2>
                    <distortionT1>0.0</distortionT1>
                    <distortionT2>0.0</distortionT2>
                </plugin>
            </sensor>
        </link>

        <joint type="fixed" name="front_camera_joint">
            <child>front_camera_link</child>
            <parent>base_link</parent>
        </joint>

        <link name="ov9281_00_link">
            <pose>0.3 0 -0.05 0 1.5708 0</pose>
            <inertial>
                <mass>1e-10</mass>
                <inertia>
                    <ixx>1e-06</ixx>
                    <ixy>0</ixy>
                    <ixz>0</ixz>
                    <iyy>1e-06</iyy>
                    <iyz>0</iyz>
                    <izz>1e-06</izz>
                </inertia>
            </inertial>

            <sensor name="ov9281_00" type="camera">
                <camera name="ov9281_00">
                    <horizontal_fov>2.094</horizontal_fov>
                    <image>
                        <width>640</width>
                        <height>480</height>
                        <format>R8G8B8</format>
                    </image>
                    <clip>
                        <near>0.02</near>
                        <far>100</far>
                    </clip>
                    <noise>
                        <type>gaussian</type>
                        <mean>0.0</mean>
                        <stddev>0.007</stddev>
                    </noise>
                    <distortion>
                        <k1>0.0</k1>
                        <k2>0.0</k2>
                        <p1>0.0</p1>
                        <p2>0.0</p2>
                        <k3>0</k3>
                    </distortion>

                    <lens>
                        <type>equidistant</type>
                        <scale_to_hfov>false</scale_to_hfov>
                    </lens>
                </camera>
                <always_on>1</always_on>
                <update_rate>10</update_rate>
                <visualize>1</visualize>

                <plugin name="camera_controller" filename="libgazebo_ros_camera.so">
                    <alwaysOn>1</alwaysOn>
                    <updateRate>0.0</updateRate>
                    <cameraName>ov9281_00</cameraName>
                    <imageTopicName>image_raw</imageTopicName>
                    <distortionK1>0.0</distortionK1>
                    <distortionK2>0.0</distortionK2>
                    <distortionT1>0.0</distortionT1>
                    <distortionT2>0.0</distortionT2>
                </plugin>
            </sensor>
        </link>

        <joint type="fixed" name="ov9281_00_joint">
            <child>ov9281_00_link</child>
            <parent>base_link</parent>
        </joint>

    </model>
</sdf>
